Workbook
Name UPDATE: 'data sheet'!$E$1

Sheet Front page
B10: TATA STEEL LTD
B11: BSE: 500470
B12: NSE: TATA STEEL
B19: Financial Modelling
G20: Report
B24: ( A Comprehensive DCF & Comparable Comps Valuation )
F36: Prepared by : Akanksha Singh

Sheet Contents list
C2: Table of Contents
A4: 1 | B4: Historical Financial Statement
A5: =1+A4 -> 2 | B5: Common Size Statement
A6: =1+A5 -> 3 | B6: Ratio Analysis
A7: =1+A6 -> 4 | B7: Forecasting
A8: =1+A7 -> 5 | B8: Regression Beta
A9: =1+A8 -> 6 | B9: Return on Market
A10: =1+A9 -> 7 | B10: Weighted Average Cost of Capital (WACC)
A11: =1+A10 -> 8 | B11: Intrinsic Growth
A12: =1+A11 -> 9 | B12: DCF Valuation
A13: =1+A12 -> 10 | B13: Comparable Copanies Valuation
A14: =1+A13 -> 11 | B14: Sensitivity Analysis
A15: =1+A14 -> 12 | B15: Football Field Analysis

Sheet HISTORICAL(FS)
B2: Historical Financial Statement- TATA STEEL LTD
B3: Years | C3: =IFERROR('data sheet'!B16,0) -> 42460 | D3: =IFERROR('data sheet'!C16,0) -> 42825 | E3: =IFERROR('data sheet'!D16,0) -> 43190 | F3: =IFERROR('data sheet'!E16,0) -> 43555 | G3: =IFERROR('data sheet'!F16,0) -> 43921 | H3: =IFERROR('data sheet'!G16,0) -> 44286 | I3: =IFERROR('data sheet'!H16,0) -> 44651 | J3: =IFERROR('data sheet'!I16,0) -> 45016 | ... L3: =IFERROR('data sheet'!K16,0) -> 45747 | M3: LTM
A5: # | B5: Income Statement
B7: Sales | C7: =IFERROR('data sheet'!B17,0) -> 101964.72 | D7: =IFERROR('data sheet'!C17,0) -> 112299.42 | E7: =IFERROR('data sheet'!D17,0) -> 123249.07 | F7: =IFERROR('data sheet'!E17,0) -> 157668.99 | G7: =IFERROR('data sheet'!F17,0) -> 139816.65 | H7: =IFERROR('data sheet'!G17,0) -> 156477.4 | I7: =IFERROR('data sheet'!H17,0) -> 243959.17 | J7: =IFERROR('data sheet'!I17,0) -> 243352.69 | ... L7: =IFERROR('data sheet'!K17,0) -> 218542.51 | M7: =IFERROR(SUM('data sheet'!H41:K41),0) -> 225087.92
B8: Sales Growth | C8: - | D8: =D7/C7-1 -> 0.10135565 | E8: =E7/D7-1 -> 0.097504065 | F8: =F7/E7-1 -> 0.27927124 | G8: =G7/F7-1 -> -0.1132267 | H8: =H7/G7-1 -> 0.11916142 | I8: =I7/H7-1 -> 0.55906968 | J8: =J7/I7-1 -> -0.0024859898 | K8: =K7/J7-1 -> -0.058277186 | ... M8: =M7/L7-1 -> 0.029950283
B10: COGS | C10: =IFERROR(SUM('data sheet'!B18,'data sheet'!B20:B22)-1*'data sheet'!B19,0) -> 79237.26 | D10: =IFERROR(SUM('data sheet'!C18,'data sheet'!C20:C22)-1*'data sheet'!C19,0) -> 77577.09 | E10: =IFERROR(SUM('data sheet'!D18,'data sheet'!D20:D22)-1*'data sheet'!D19,0) -> 84710.05 | F10: =IFERROR(SUM('data sheet'!E18,'data sheet'!E20:E22)-1*'data sheet'!E19,0) -> 105590.05 | G10: =IFERROR(SUM('data sheet'!F18,'data sheet'!F20:F22)-1*'data sheet'!F19,0) -> 102560.94 | H10: =IFERROR(SUM('data sheet'!G18,'data sheet'!G20:G22)-1*'data sheet'!G19,0) -> 102979.74 | I10: =IFERROR(SUM('data sheet'!H18,'data sheet'!H20:H22)-1*'data sheet'!H19,0) -> 143605.19 | J10: =IFERROR(SUM('data sheet'!I18,'data sheet'!I20:I22)-1*'data sheet'!I19,0) -> 178329.36 | ... L10: =IFERROR(SUM('data sheet'!K18,'data sheet'!K20:K22)-1*'data sheet'!K19,0) -> 171714.99 | M10: =IFERROR(SUM('data sheet'!H42:K42),0) -> 194004.92
B11: COGS % Sales | C11: =C10/C7 -> 0.77710467 | D11: =D10/D7 -> 0.69080579 | E11: =E10/E7 -> 0.68730782 | F11: =F10/F7 -> 0.66969447 | G11: =G10/G7 -> 0.73353882 | H11: =H10/H7 -> 0.65811255 | I11: =I10/I7 -> 0.58864436 | J11: =J10/J7 -> 0.73280209 | ... M11: =M10/M7 -> 0.86190729
B13: Gross Profit | C13: =C7-'HISTORICAL(FS)'!C10 -> 22727.46 | D13: =D7-'HISTORICAL(FS)'!D10 -> 34722.33 | E13: =E7-'HISTORICAL(FS)'!E10 -> 38539.02 | F13: =F7-'HISTORICAL(FS)'!F10 -> 52078.94 | G13: =G7-'HISTORICAL(FS)'!G10 -> 37255.71 | H13: =H7-'HISTORICAL(FS)'!H10 -> 53497.66 | I13: =I7-'HISTORICAL(FS)'!I10 -> 100353.98 | J13: =J7-'HISTORICAL(FS)'!J10 -> 65023.33 | ... M13: =M7-'HISTORICAL(FS)'!M10 -> 31083
B14: Gross Margins | C14: =C13/C7 -> 0.22289533 | D14: =D13/D7 -> 0.30919421 | E14: =E13/E7 -> 0.31269218 | F14: =F13/F7 -> 0.33030553 | G14: =G13/G7 -> 0.26646118 | H14: =H13/H7 -> 0.34188745 | I14: =I13/I7 -> 0.41135564 | J14: =J13/J7 -> 0.26719791 | ... M14: =M13/M7 -> 0.13809271
B16: Selling & General Expenses | C16: =IFERROR(SUM('data sheet'!B23:B24),0) -> 23352.7 | D16: =IFERROR(SUM('data sheet'!C23:C24),0) -> 21578.7 | E16: =IFERROR(SUM('data sheet'!D23:D24),0) -> 17105.83 | F16: =IFERROR(SUM('data sheet'!E23:E24),0) -> 22760.72 | G16: =IFERROR(SUM('data sheet'!F23:F24),0) -> 19792.65 | H16: =IFERROR(SUM('data sheet'!G23:G24),0) -> 22993.4 | I16: =IFERROR(SUM('data sheet'!H23:H24),0) -> 36864.03 | J16: =IFERROR(SUM('data sheet'!I23:I24),0) -> 32723.17 | ... L16: =IFERROR(SUM('data sheet'!K23:K24),0) -> 21529.07
B17: S&G Exp % Sales | C17: =C16/C7 -> 0.22902726 | D17: =D16/D7 -> 0.19215326 | E17: =E16/E7 -> 0.13879074 | F17: =F16/F7 -> 0.14435762 | G17: =G16/G7 -> 0.14156147 | H17: =H16/H7 -> 0.1469439 | I17: =I16/I7 -> 0.15110738 | J17: =J16/J7 -> 0.13446808 | ... M17: =M16/M7 -> 0
B19: EBITDA | C19: =IFERROR(C13-C16,0) -> -625.24 | D19: =IFERROR(D13-D16,0) -> 13143.63 | E19: =IFERROR(E13-E16,0) -> 21433.19 | F19: =IFERROR(F13-F16,0) -> 29318.22 | G19: =IFERROR(G13-G16,0) -> 17463.06 | H19: =IFERROR(H13-H16,0) -> 30504.26 | I19: =IFERROR(I13-I16,0) -> 63489.95 | J19: =IFERROR(J13-J16,0) -> 32300.16 | ... L19: =IFERROR(L13-L16,0) -> 25298.45 | M19: =IFERROR(SUM('data sheet'!H51:K51),0) -> 31974.76
B20: EBITDA Margins | C20: =C19/C7 -> -0.0061319248 | D20: =D19/D7 -> 0.11704094 | E20: =E19/E7 -> 0.17390143 | F20: =F19/F7 -> 0.18594792 | G20: =G19/G7 -> 0.12489972 | H20: =H19/H7 -> 0.19494355 | I20: =I19/I7 -> 0.26024826 | J20: =J19/J7 -> 0.13272983 | ... M20: =M19/M7 -> 0.14205454
B22: Interest | C22: =IFERROR('data sheet'!B27,0) -> 4221.41 | D22: =IFERROR('data sheet'!C27,0) -> 5072.2 | E22: =IFERROR('data sheet'!D27,0) -> 5454.74 | F22: =IFERROR('data sheet'!E27,0) -> 7660.1 | G22: =IFERROR('data sheet'!F27,0) -> 7533.46 | H22: =IFERROR('data sheet'!G27,0) -> 7606.71 | I22: =IFERROR('data sheet'!H27,0) -> 5462.2 | J22: =IFERROR('data sheet'!I27,0) -> 6298.7 | ... M22: =IFERROR('data sheet'!L27,0) -> 0
B23: Interest % Sales | C23: =C22/C7 -> 0.041400692 | D23: =D22/D7 -> 0.045166752 | E23: =E22/E7 -> 0.044257859 | F23: =F22/F7 -> 0.048583428 | G23: =G22/G7 -> 0.053880993 | H23: =H22/H7 -> 0.048612196 | I23: =I22/I7 -> 0.022389812 | J23: =J22/J7 -> 0.02588301 | ... M23: =M22/M7 -> 0
B25: Depreciation | C25: =IFERROR('data sheet'!B26,0) -> 5306.35 | D25: =IFERROR('data sheet'!C26,0) -> 5672.88 | E25: =IFERROR('data sheet'!D26,0) -> 5741.7 | F25: =IFERROR('data sheet'!E26,0) -> 7341.83 | G25: =IFERROR('data sheet'!F26,0) -> 8440.73 | H25: =IFERROR('data sheet'!G26,0) -> 9233.64 | I25: =IFERROR('data sheet'!H26,0) -> 9100.87 | J25: =IFERROR('data sheet'!I26,0) -> 9335.2 | ... L25: =IFERROR('data sheet'!K26,0) -> 10421.33 | M25: =IFERROR(SUM('data sheet'!H44:K44),0) -> 11406.08
B26: Depreciation % Sales | C26: =C25/C7 -> 0.052041039 | D26: =D25/D7 -> 0.050515666 | E26: =E25/E7 -> 0.046586153 | F26: =F25/F7 -> 0.046564832 | G26: =G25/G7 -> 0.060369992 | H26: =H25/H7 -> 0.059009416 | I26: =I25/I7 -> 0.03730489 | J26: =J25/J7 -> 0.038360784 | ... M26: =M25/M7 -> 0.050673888
B28: Earnings before Tax | C28: =IFERROR(C19-SUM(C22,C25),0) -> -10153 | D28: =IFERROR(D19-SUM(D22,D25),0) -> 2398.55 | E28: =IFERROR(E19-SUM(E22,E25),0) -> 10236.75 | F28: =IFERROR(F19-SUM(F22,F25),0) -> 14316.29 | G28: =IFERROR(G19-SUM(G22,G25),0) -> 1488.87 | H28: =IFERROR(H19-SUM(H22,H25),0) -> 13663.91 | I28: =IFERROR(I19-SUM(I22,I25),0) -> 48926.88 | J28: =IFERROR(J19-SUM(J22,J25),0) -> 16666.26 | ... M28: =IFERROR(M19-SUM(M22,M25),0) -> 20568.68
B29: EBT % Sales | C29: =C28/C7 -> -0.099573656 | D29: =D28/D7 -> 0.021358525 | E29: =E28/E7 -> 0.083057422 | F29: =F28/F7 -> 0.090799656 | G29: =G28/G7 -> 0.010648732 | H29: =H28/H7 -> 0.087321939 | I29: =I28/I7 -> 0.20055356 | J29: =J28/J7 -> 0.068486032 | ... M29: =M28/M7 -> 0.091380648
B31: Tax | C31: =IFERROR('data sheet'!B29,0) -> 689.96 | D31: =IFERROR('data sheet'!C29,0) -> 2778.01 | E31: =IFERROR('data sheet'!D29,0) -> 3392.33 | F31: =IFERROR('data sheet'!E29,0) -> 6718.43 | G31: =IFERROR('data sheet'!F29,0) -> -2568.41 | H31: =IFERROR('data sheet'!G29,0) -> 5653.9 | I31: =IFERROR('data sheet'!H29,0) -> 8477.55 | J31: =IFERROR('data sheet'!I29,0) -> 10159.77 | ... L31: =IFERROR('data sheet'!K29,0) -> 5239.09 | M31: =IFERROR(SUM('data sheet'!H47:K47),0) -> 4236.31
B32: Effective Tax Rate | C32: =C31/C28 -> -0.067956269 | D32: =D31/D28 -> 1.1582039 | E32: =E31/E28 -> 0.3313874 | F32: =F31/F28 -> 0.46928569 | G32: =G31/G28 -> -1.7250734 | H32: =H31/H28 -> 0.41378346 | I32: =I31/I28 -> 0.17326979 | J32: =J31/J28 -> 0.60960107 | ... M32: =M31/M28 -> 0.20595925
B34: Net Profit | C34: =IFERROR(C28-C31,0) -> -10842.96 | D34: =IFERROR(D28-D31,0) -> -379.46 | E34: =IFERROR(E28-E31,0) -> 6844.42 | F34: =IFERROR(F28-F31,0) -> 7597.86 | G34: =IFERROR(G28-G31,0) -> 4057.28 | H34: =IFERROR(H28-H31,0) -> 8010.01 | I34: =IFERROR(I28-I31,0) -> 40449.33 | J34: =IFERROR(J28-J31,0) -> 6506.49 | ... M34: =IFERROR(M28-M31,0) -> 16332.37
B35: Net Margins | C35: =C34/C7 -> -0.10634031 | D35: =D34/D7 -> -0.0033790023 | E35: =E34/E7 -> 0.055533239 | F35: =F34/F7 -> 0.048188677 | G35: =G34/G7 -> 0.029018575 | H35: =H34/H7 -> 0.051189565 | I35: =I34/I7 -> 0.16580369 | J35: =J34/J7 -> 0.026736873 | ... M35: =M34/M7 -> 0.072559958
B37: No of Equity Shares | C37: =IFERROR('data sheet'!B93,0) -> 1126.62 | D37: =IFERROR('data sheet'!C93,0) -> 1126.62 | E37: =IFERROR('data sheet'!D93,0) -> 1126.48 | F37: =IFERROR('data sheet'!E93,0) -> 1126.49 | G37: =IFERROR('data sheet'!F93,0) -> 1126.49 | H37: =IFERROR('data sheet'!G93,0) -> 1196.59 | I37: =IFERROR('data sheet'!H93,0) -> 1221.3 | J37: =IFERROR('data sheet'!I93,0) -> 1222.15 | ... M37: =IFERROR('data sheet'!L93,0) -> 0
B39: Earning per Share | C39: =IFERROR(C34/C37,0) -> -9.6243276 | D39: =IFERROR(D34/D37,0) -> -0.33681277 | E39: =IFERROR(E34/E37,0) -> 6.0759357 | F39: =IFERROR(F34/F37,0) -> 6.7447203 | G39: =IFERROR(G34/G37,0) -> 3.6017009 | H39: =IFERROR(H34/H37,0) -> 6.6940305 | I39: =IFERROR(I34/I37,0) -> 33.119897 | J39: =IFERROR(J34/J37,0) -> 5.3238064 | ... M39: =IFERROR(M34/M37,0) -> 0
B40: EPS Growth % | D40: =IFERROR(D39/C39-1,0) -> -0.96500402 | E40: =IFERROR(E39/D39-1,0) -> -19.039505 | F40: =IFERROR(F39/E39-1,0) -> 0.11007106 | G40: =IFERROR(G39/F39-1,0) -> -0.465997 | H40: =IFERROR(H39/G39-1,0) -> 0.85857482 | I40: =IFERROR(I39/H39-1,0) -> 3.9476764 | J40: =IFERROR(J39/I39-1,0) -> -0.83925655 | K40: =IFERROR(K39/J39-1,0) -> -0.8351453 | ... M40: =IFERROR(M39/L39-1,0) -> -1
B42: Divident per Share | C42: =IFERROR('data sheet'!B31/'HISTORICAL(FS)'!C37,0) -> 0.68895457 | D42: =IFERROR('data sheet'!C31/'HISTORICAL(FS)'!D37,0) -> 0.86119543 | E42: =IFERROR('data sheet'!D31/'HISTORICAL(FS)'!E37,0) -> 1.0163962 | F42: =IFERROR('data sheet'!E31/'HISTORICAL(FS)'!F37,0) -> 1.32129 | G42: =IFERROR('data sheet'!F31/'HISTORICAL(FS)'!G37,0) -> 1.0163872 | H42: =IFERROR('data sheet'!G31/'HISTORICAL(FS)'!H37,0) -> 2.5021269 | I42: =IFERROR('data sheet'!H31/'HISTORICAL(FS)'!I37,0) -> 5.0996234 | J42: =IFERROR('data sheet'!I31/'HISTORICAL(FS)'!J37,0) -> 3.5973162 | ... M42: =IFERROR('data sheet'!L31/'HISTORICAL(FS)'!M37,0) -> 0
B43: Divident payout ratio | C43: =IFERROR(C42/C39,0) -> -0.071584696 | D43: =IFERROR(D42/D39,0) -> -2.5568966 | E43: =IFERROR(E42/E39,0) -> 0.16728225 | F43: =IFERROR(F42/F39,0) -> 0.1958999 | G43: =IFERROR(G42/G39,0) -> 0.28219645 | H43: =IFERROR(H42/H39,0) -> 0.3737848 | I43: =IFERROR(I42/I39,0) -> 0.15397461 | J43: =IFERROR(J42/J39,0) -> 0.6757038 | ... M43: =IFERROR(M42/M39,0) -> 0
B45: Retained Earnings | C45: =IFERROR(IF(C39>C42,1-C43,0),0) -> 0 | D45: =IFERROR(IF(D39>D42,1-D43,0),0) -> 0 | E45: =IFERROR(IF(E39>E42,1-E43,0),0) -> 0.83271775 | F45: =IFERROR(IF(F39>F42,1-F43,0),0) -> 0.8041001 | G45: =IFERROR(IF(G39>G42,1-G43,0),0) -> 0.71780355 | H45: =IFERROR(IF(H39>H42,1-H43,0),0) -> 0.6262152 | I45: =IFERROR(IF(I39>I42,1-I43,0),0) -> 0.84602539 | J45: =IFERROR(IF(J39>J42,1-J43,0),0) -> 0.3242962 | ... M45: =IFERROR(IF(M39>M42,1-M43,0),0) -> 0
A48: # | B48: Balance Sheet
B50: Equity Share Capital | C50: =IFERROR('data sheet'!B56,0) -> 970.24 | D50: =IFERROR('data sheet'!C56,0) -> 970.24 | E50: =IFERROR('data sheet'!D56,0) -> 1144.95 | F50: =IFERROR('data sheet'!E56,0) -> 1144.94 | G50: =IFERROR('data sheet'!F56,0) -> 1144.95 | H50: =IFERROR('data sheet'!G56,0) -> 1197.61 | I50: =IFERROR('data sheet'!H56,0) -> 1221.21 | J50: =IFERROR('data sheet'!I56,0) -> 1221.24 | ... L50: =IFERROR('data sheet'!K56,0) -> 1247.44
B51: Reserves | C51: =IFERROR('data sheet'!B57,0) -> 42762.31 | D51: =IFERROR('data sheet'!C57,0) -> 36849.08 | E51: =IFERROR('data sheet'!D57,0) -> 59725.67 | F51: =IFERROR('data sheet'!E57,0) -> 67780.14 | G51: =IFERROR('data sheet'!F57,0) -> 72431.35 | H51: =IFERROR('data sheet'!G57,0) -> 73041.16 | I51: =IFERROR('data sheet'!H57,0) -> 113221.83 | J51: =IFERROR('data sheet'!I57,0) -> 101860.86 | ... L51: =IFERROR('data sheet'!K57,0) -> 89922.19
B52: Borrowings | C52: =IFERROR('data sheet'!B58,0) -> 81986.93 | D52: =IFERROR('data sheet'!C58,0) -> 83014.49 | E52: =IFERROR('data sheet'!D58,0) -> 92147.05 | F52: =IFERROR('data sheet'!E58,0) -> 100816.22 | G52: =IFERROR('data sheet'!F58,0) -> 116328.2 | H52: =IFERROR('data sheet'!G58,0) -> 88501.41 | I52: =IFERROR('data sheet'!H58,0) -> 75561.35 | J52: =IFERROR('data sheet'!I58,0) -> 84893.05 | ... L52: =IFERROR('data sheet'!K58,0) -> 94801.05
B53: Other Liabilities | C53: =IFERROR('data sheet'!B59,0) -> 51164.51 | D53: =IFERROR('data sheet'!C59,0) -> 51613.56 | E53: =IFERROR('data sheet'!D59,0) -> 55704.47 | F53: =IFERROR('data sheet'!E59,0) -> 63032.14 | G53: =IFERROR('data sheet'!F59,0) -> 59244.62 | H53: =IFERROR('data sheet'!G59,0) -> 81169.01 | I53: =IFERROR('data sheet'!H59,0) -> 92417.28 | J53: =IFERROR('data sheet'!I59,0) -> 97420.63 | ... L53: =IFERROR('data sheet'!K59,0) -> 89487.9
B54: Total Liabilities | C54: =IFERROR('data sheet'!B60,0) -> 176883.99 | D54: =IFERROR('data sheet'!C60,0) -> 172447.37 | E54: =IFERROR('data sheet'!D60,0) -> 208722.14 | F54: =IFERROR('data sheet'!E60,0) -> 232773.44 | G54: =IFERROR('data sheet'!F60,0) -> 249149.12 | H54: =IFERROR('data sheet'!G60,0) -> 243909.19 | I54: =IFERROR('data sheet'!H60,0) -> 282421.67 | J54: =IFERROR('data sheet'!I60,0) -> 285395.78 | ... L54: =IFERROR('data sheet'!K60,0) -> 275458.58
B56: Fixed Assets Net Block | C56: =IFERROR('data sheet'!B61,0) -> 72199.76 | D56: =IFERROR('data sheet'!C61,0) -> 92006.55 | E56: =IFERROR('data sheet'!D61,0) -> 96104.89 | F56: =IFERROR('data sheet'!E61,0) -> 124441.91 | G56: =IFERROR('data sheet'!F61,0) -> 134550.66 | H56: =IFERROR('data sheet'!G61,0) -> 135775.18 | I56: =IFERROR('data sheet'!H61,0) -> 133287.83 | J56: =IFERROR('data sheet'!I61,0) -> 146621.46 | ... L56: =IFERROR('data sheet'!K61,0) -> 150914.06
B57: Capital Work in Progress | C57: =IFERROR('data sheet'!B62,0) -> 35996.09 | D57: =IFERROR('data sheet'!C62,0) -> 15784.13 | E57: =IFERROR('data sheet'!D62,0) -> 16614.41 | F57: =IFERROR('data sheet'!E62,0) -> 18641.21 | G57: =IFERROR('data sheet'!F62,0) -> 19496.83 | H57: =IFERROR('data sheet'!G62,0) -> 19007.4 | I57: =IFERROR('data sheet'!H62,0) -> 22045.55 | J57: =IFERROR('data sheet'!I62,0) -> 31213.02 | ... L57: =IFERROR('data sheet'!K62,0) -> 41622.35
B58: Investments | C58: =IFERROR('data sheet'!B63,0) -> 10713.71 | D58: =IFERROR('data sheet'!C63,0) -> 12457.12 | E58: =IFERROR('data sheet'!D63,0) -> 17899.47 | F58: =IFERROR('data sheet'!E63,0) -> 5738.17 | G58: =IFERROR('data sheet'!F63,0) -> 6285.18 | H58: =IFERROR('data sheet'!G63,0) -> 10681.93 | I58: =IFERROR('data sheet'!H63,0) -> 13139.85 | J58: =IFERROR('data sheet'!I63,0) -> 8410.31 | ... L58: =IFERROR('data sheet'!K63,0) -> 6194.11
B59: Other Assets | C59: =IFERROR('data sheet'!B64-SUM('data sheet'!B66:B68),0) -> 19708.54 | D59: =IFERROR('data sheet'!C64-SUM('data sheet'!C66:C68),0) -> 10887.88 | E59: =IFERROR('data sheet'!D64-SUM('data sheet'!D66:D68),0) -> 29418.96 | F59: =IFERROR('data sheet'!E64-SUM('data sheet'!E66:E68),0) -> 37143.68 | G59: =IFERROR('data sheet'!F64-SUM('data sheet'!F66:F68),0) -> 41808.1 | H59: =IFERROR('data sheet'!G64-SUM('data sheet'!G66:G68),0) -> 29846.28 | I59: =IFERROR('data sheet'!H64-SUM('data sheet'!H66:H68),0) -> 36978.69 | J59: =IFERROR('data sheet'!I64-SUM('data sheet'!I66:I68),0) -> 23121.16 | ... L59: =IFERROR('data sheet'!K64-SUM('data sheet'!K66:K68),0) -> 15231.08
B60: Total Non Current Assets | C60: =IFERROR(SUM(C56:C59),0) -> 138618.1 | D60: =IFERROR(SUM(D56:D59),0) -> 131135.68 | E60: =IFERROR(SUM(E56:E59),0) -> 160037.73 | F60: =IFERROR(SUM(F56:F59),0) -> 185964.97 | G60: =IFERROR(SUM(G56:G59),0) -> 202140.77 | H60: =IFERROR(SUM(H56:H59),0) -> 195310.79 | I60: =IFERROR(SUM(I56:I59),0) -> 205451.92 | J60: =IFERROR(SUM(J56:J59),0) -> 209365.95 | ... L60: =IFERROR(SUM(L56:L59),0) -> 213961.6
...

Sheet common size statement
B3: Common Size Income Statement- TATA STEEL LTD
B5: Particulars | D5: 42460 | E5: 42825 | F5: 43190 | G5: 43555 | H5: 43921 | I5: 44286 | J5: 44651 | K5: 45016 | L5: 45382 | M5: 45747
B7: Sales | D7: ='data sheet'!B17/'data sheet'!B$17 -> 1 | E7: ='data sheet'!C17/'data sheet'!C$17 -> 1 | F7: ='data sheet'!D17/'data sheet'!D$17 -> 1 | G7: ='data sheet'!E17/'data sheet'!E$17 -> 1 | H7: ='data sheet'!F17/'data sheet'!F$17 -> 1 | I7: ='data sheet'!G17/'data sheet'!G$17 -> 1 | J7: ='data sheet'!H17/'data sheet'!H$17 -> 1 | K7: ='data sheet'!I17/'data sheet'!I$17 -> 1 | ... M7: ='data sheet'!K17/'data sheet'!K$17 -> 1
B8: Raw Material Cost | D8: ='data sheet'!B18/'data sheet'!B$17 -> 0.37950646 | E8: ='data sheet'!C18/'data sheet'!C$17 -> 0.3904119 | F8: ='data sheet'!D18/'data sheet'!D$17 -> 0.37433962 | G8: ='data sheet'!E18/'data sheet'!E$17 -> 0.38610668 | H8: ='data sheet'!F18/'data sheet'!F$17 -> 0.41511501 | I8: ='data sheet'!G18/'data sheet'!G$17 -> 0.3521327 | J8: ='data sheet'!H18/'data sheet'!H$17 -> 0.37332727 | K8: ='data sheet'!I18/'data sheet'!I$17 -> 0.47912842 | ... M8: ='data sheet'!K18/'data sheet'!K$17 -> 0.43514326
B9: Change in Inventory | D9: ='data sheet'!B19/'data sheet'!B$17 -> -0.018880942 | E9: ='data sheet'!C19/'data sheet'!C$17 -> 0.040410983 | F9: ='data sheet'!D19/'data sheet'!D$17 -> -0.00080576673 | G9: ='data sheet'!E19/'data sheet'!E$17 -> 0.00061337363 | H9: ='data sheet'!F19/'data sheet'!F$17 -> 0.0040427231 | I9: ='data sheet'!G19/'data sheet'!G$17 -> -0.0096932209 | J9: ='data sheet'!H19/'data sheet'!H$17 -> 0.031144023 | K9: ='data sheet'!I19/'data sheet'!I$17 -> 0.01380256 | ... M9: ='data sheet'!K19/'data sheet'!K$17 -> 0.00044224806
B10: Power and Fuel | D10: ='data sheet'!B20/'data sheet'!B$17 -> 0.048976646 | E10: ='data sheet'!C20/'data sheet'!C$17 -> 0.046490267 | F10: ='data sheet'!D20/'data sheet'!D$17 -> 0.036028101 | G10: ='data sheet'!E20/'data sheet'!E$17 -> 0.033719757 | H10: ='data sheet'!F20/'data sheet'!F$17 -> 0.03804926 | I10: ='data sheet'!G20/'data sheet'!G$17 -> 0.036480795 | J10: ='data sheet'!H20/'data sheet'!H$17 -> 0.032908335 | K10: ='data sheet'!I20/'data sheet'!I$17 -> 0.039148571 | ... M10: ='data sheet'!K20/'data sheet'!K$17 -> 0.060056279
B11: Other Mfr. Exp | D11: ='data sheet'!B21/'data sheet'!B$17 -> 0.15725321 | E11: ='data sheet'!C21/'data sheet'!C$17 -> 0.14068764 | F11: ='data sheet'!D21/'data sheet'!D$17 -> 0.13757337 | G11: ='data sheet'!E21/'data sheet'!E$17 -> 0.13150512 | H11: ='data sheet'!F21/'data sheet'!F$17 -> 0.15186096 | I11: ='data sheet'!G21/'data sheet'!G$17 -> 0.13257461 | J11: ='data sheet'!H21/'data sheet'!H$17 -> 0.11819215 | K11: ='data sheet'!I21/'data sheet'!I$17 -> 0.1362008 | ... M11: ='data sheet'!K21/'data sheet'!K$17 -> 0.17708454
B12: Employee Cost | D12: ='data sheet'!B22/'data sheet'!B$17 -> 0.17248741 | E12: ='data sheet'!C22/'data sheet'!C$17 -> 0.15362697 | F12: ='data sheet'!D22/'data sheet'!D$17 -> 0.13856096 | G12: ='data sheet'!E22/'data sheet'!E$17 -> 0.11897628 | H12: ='data sheet'!F22/'data sheet'!F$17 -> 0.13255632 | I12: ='data sheet'!G22/'data sheet'!G$17 -> 0.12723122 | J12: ='data sheet'!H22/'data sheet'!H$17 -> 0.095360629 | K12: ='data sheet'!I22/'data sheet'!I$17 -> 0.092126863 | ... M12: ='data sheet'!K22/'data sheet'!K$17 -> 0.11388626
B13: Selling and admin | D13: ='data sheet'!B23/'data sheet'!B$17 -> 0.12659692 | E13: ='data sheet'!C23/'data sheet'!C$17 -> 0.12263928 | F13: ='data sheet'!D23/'data sheet'!D$17 -> 0.11703025 | G13: ='data sheet'!E23/'data sheet'!E$17 -> 0.10729529 | H13: ='data sheet'!F23/'data sheet'!F$17 -> 0.11156804 | I13: ='data sheet'!G23/'data sheet'!G$17 -> 0.11189967 | J13: ='data sheet'!H23/'data sheet'!H$17 -> 0.11250108 | K13: ='data sheet'!I23/'data sheet'!I$17 -> 0.10486804 | ... M13: ='data sheet'!K23/'data sheet'!K$17 -> 0.055537296
B14: Other Expenses | D14: ='data sheet'!B24/'data sheet'!B$17 -> 0.10243033 | E14: ='data sheet'!C24/'data sheet'!C$17 -> 0.069513983 | F14: ='data sheet'!D24/'data sheet'!D$17 -> 0.021760489 | G14: ='data sheet'!E24/'data sheet'!E$17 -> 0.037062329 | H14: ='data sheet'!F24/'data sheet'!F$17 -> 0.029993424 | I14: ='data sheet'!G24/'data sheet'!G$17 -> 0.03504423 | J14: ='data sheet'!H24/'data sheet'!H$17 -> 0.038606296 | K14: ='data sheet'!I24/'data sheet'!I$17 -> 0.029600043 | ... M14: ='data sheet'!K24/'data sheet'!K$17 -> 0.042974751
B15: Other Income | D15: ='data sheet'!B25/'data sheet'!B$17 -> 0.10146519 | E15: ='data sheet'!C25/'data sheet'!C$17 -> -0.033741136 | F15: ='data sheet'!D25/'data sheet'!D$17 -> 0.0884259 | G15: ='data sheet'!E25/'data sheet'!E$17 -> 0.0096677857 | H15: ='data sheet'!F25/'data sheet'!F$17 -> -0.020624368 | I15: ='data sheet'!G25/'data sheet'!G$17 -> 0.0011489199 | J15: ='data sheet'!H25/'data sheet'!H$17 -> 0.0053287196 | K15: ='data sheet'!I25/'data sheet'!I$17 -> 0.006446857 | ... M15: ='data sheet'!K25/'data sheet'!K$17 -> 0.0040115765
B16: Depreciation | D16: ='data sheet'!B26/'data sheet'!B$17 -> 0.052041039 | E16: ='data sheet'!C26/'data sheet'!C$17 -> 0.050515666 | F16: ='data sheet'!D26/'data sheet'!D$17 -> 0.046586153 | G16: ='data sheet'!E26/'data sheet'!E$17 -> 0.046564832 | H16: ='data sheet'!F26/'data sheet'!F$17 -> 0.060369992 | I16: ='data sheet'!G26/'data sheet'!G$17 -> 0.059009416 | J16: ='data sheet'!H26/'data sheet'!H$17 -> 0.03730489 | K16: ='data sheet'!I26/'data sheet'!I$17 -> 0.038360784 | ... M16: ='data sheet'!K26/'data sheet'!K$17 -> 0.047685597
B17: Interest | D17: ='data sheet'!B27/'data sheet'!B$17 -> 0.041400692 | E17: ='data sheet'!C27/'data sheet'!C$17 -> 0.045166752 | F17: ='data sheet'!D27/'data sheet'!D$17 -> 0.044257859 | G17: ='data sheet'!E27/'data sheet'!E$17 -> 0.048583428 | H17: ='data sheet'!F27/'data sheet'!F$17 -> 0.053880993 | I17: ='data sheet'!G27/'data sheet'!G$17 -> 0.048612196 | J17: ='data sheet'!H27/'data sheet'!H$17 -> 0.022389812 | K17: ='data sheet'!I27/'data sheet'!I$17 -> 0.02588301 | ... M17: ='data sheet'!K27/'data sheet'!K$17 -> 0.03359049
B18: Profit before tax | D18: ='data sheet'!B28/'data sheet'!B$17 -> 0.0018915366 | E18: ='data sheet'!C28/'data sheet'!C$17 -> -0.012382611 | F18: ='data sheet'!D28/'data sheet'!D$17 -> 0.17148332 | G18: ='data sheet'!E28/'data sheet'!E$17 -> 0.10046744 | H18: ='data sheet'!F28/'data sheet'!F$17 -> -0.0099756359 | I18: ='data sheet'!G28/'data sheet'!G$17 -> 0.088470859 | J18: ='data sheet'!H28/'data sheet'!H$17 -> 0.20588228 | K18: ='data sheet'!I28/'data sheet'!I$17 -> 0.074932889 | ... M18: ='data sheet'!K28/'data sheet'!K$17 -> 0.038495348
... B22: EBITDA | D22: ='data sheet'!B32/'data sheet'!B$17 -> 0.096454342 | E22: ='data sheet'!C32/'data sheet'!C$17 -> 0.082656616 | F22: ='data sheet'!D32/'data sheet'!D$17 -> 0.22736967 | G22: ='data sheet'!E32/'data sheet'!E$17 -> 0.20256799 | H22: ='data sheet'!F32/'data sheet'!F$17 -> 0.10701386 | I22: ='data sheet'!G32/'data sheet'!G$17 -> 0.19162173 | J22: ='data sheet'!H32/'data sheet'!H$17 -> 0.2590374 | K22: ='data sheet'!I32/'data sheet'!I$17 -> 0.14199173 | ... M22: ='data sheet'!K32/'data sheet'!K$17 -> 0.12090041
B24: Common Size Balance Sheet- TATA STEEL LTD
B26: Particulars | D26: 42460 | E26: 42825 | F26: 43190 | G26: 43555 | H26: 43921 | I26: 44286 | J26: 44651 | K26: 45016 | L26: 45382 | M26: 45747
B28: Total Liabilities | D28: ='data sheet'!B60/'data sheet'!B$60 -> 1 | E28: ='data sheet'!C60/'data sheet'!C$60 -> 1 | F28: ='data sheet'!D60/'data sheet'!D$60 -> 1 | G28: ='data sheet'!E60/'data sheet'!E$60 -> 1 | H28: ='data sheet'!F60/'data sheet'!F$60 -> 1 | I28: ='data sheet'!G60/'data sheet'!G$60 -> 1 | J28: ='data sheet'!H60/'data sheet'!H$60 -> 1 | K28: ='data sheet'!I60/'data sheet'!I$60 -> 1 | ... M28: ='data sheet'!K60/'data sheet'!K$60 -> 1
B29: Equity Share Capital | D29: ='data sheet'!B56/'data sheet'!B$60 -> 0.005485177 | E29: ='data sheet'!C56/'data sheet'!C$60 -> 0.0056262963 | F29: ='data sheet'!D56/'data sheet'!D$60 -> 0.0054855225 | G29: ='data sheet'!E56/'data sheet'!E$60 -> 0.0049186883 | H29: ='data sheet'!F56/'data sheet'!F$60 -> 0.0045954407 | I29: ='data sheet'!G56/'data sheet'!G$60 -> 0.0049100651 | J29: ='data sheet'!H56/'data sheet'!H$60 -> 0.0043240662 | K29: ='data sheet'!I56/'data sheet'!I$60 -> 0.0042791102 | ... M29: ='data sheet'!K56/'data sheet'!K$60 -> 0.0045285937
B30: Reserves | D30: ='data sheet'!B57/'data sheet'!B$60 -> 0.24175342 | E30: ='data sheet'!C57/'data sheet'!C$60 -> 0.21368305 | F30: ='data sheet'!D57/'data sheet'!D$60 -> 0.28614918 | G30: ='data sheet'!E57/'data sheet'!E$60 -> 0.29118503 | H30: ='data sheet'!F57/'data sheet'!F$60 -> 0.29071485 | I30: ='data sheet'!G57/'data sheet'!G$60 -> 0.29946047 | J30: ='data sheet'!H57/'data sheet'!H$60 -> 0.4008964 | K30: ='data sheet'!I57/'data sheet'!I$60 -> 0.35691088 | ... M30: ='data sheet'!K57/'data sheet'!K$60 -> 0.32644541
B31: Borrowings | D31: ='data sheet'!B58/'data sheet'!B$60 -> 0.46350679 | E31: ='data sheet'!C58/'data sheet'!C$60 -> 0.48139029 | F31: ='data sheet'!D58/'data sheet'!D$60 -> 0.44148191 | G31: ='data sheet'!E58/'data sheet'!E$60 -> 0.43310878 | H31: ='data sheet'!F58/'data sheet'!F$60 -> 0.46690191 | I31: ='data sheet'!G58/'data sheet'!G$60 -> 0.36284574 | J31: ='data sheet'!H58/'data sheet'!H$60 -> 0.26754799 | K31: ='data sheet'!I58/'data sheet'!I$60 -> 0.29745727 | ... M31: ='data sheet'!K58/'data sheet'!K$60 -> 0.34415719
B32: Other Liabilities | D32: ='data sheet'!B59/'data sheet'!B$60 -> 0.28925461 | E32: ='data sheet'!C59/'data sheet'!C$60 -> 0.29930036 | F32: ='data sheet'!D59/'data sheet'!D$60 -> 0.26688338 | G32: ='data sheet'!E59/'data sheet'!E$60 -> 0.27078751 | H32: ='data sheet'!F59/'data sheet'!F$60 -> 0.2377878 | I32: ='data sheet'!G59/'data sheet'!G$60 -> 0.33278373 | J32: ='data sheet'!H59/'data sheet'!H$60 -> 0.32723155 | K32: ='data sheet'!I59/'data sheet'!I$60 -> 0.34135273 | ... M32: ='data sheet'!K59/'data sheet'!K$60 -> 0.32486881
B34: Total Assets | D34: ='data sheet'!B65/'data sheet'!B$65 -> 1 | E34: ='data sheet'!C65/'data sheet'!C$65 -> 1 | F34: ='data sheet'!D65/'data sheet'!D$65 -> 1 | G34: ='data sheet'!E65/'data sheet'!E$65 -> 1 | H34: ='data sheet'!F65/'data sheet'!F$65 -> 1 | I34: ='data sheet'!G65/'data sheet'!G$65 -> 1 | J34: ='data sheet'!H65/'data sheet'!H$65 -> 1 | K34: ='data sheet'!I65/'data sheet'!I$65 -> 1 | ... M34: ='data sheet'!K65/'data sheet'!K$65 -> 1
B35: Net Block | D35: ='data sheet'!B61/'data sheet'!B$65 -> 0.40817578 | E35: ='data sheet'!C61/'data sheet'!C$65 -> 0.53353409 | F35: ='data sheet'!D61/'data sheet'!D$65 -> 0.46044416 | G35: ='data sheet'!E61/'data sheet'!E$65 -> 0.53460528 | H35: ='data sheet'!F61/'data sheet'!F$65 -> 0.54004068 | I35: ='data sheet'!G61/'data sheet'!G$65 -> 0.55666283 | J35: ='data sheet'!H61/'data sheet'!H$65 -> 0.47194619 | K35: ='data sheet'!I61/'data sheet'!I$65 -> 0.51374782 | ... M35: ='data sheet'!K61/'data sheet'!K$65 -> 0.5478648
B36: Capital Work in Progress | D36: ='data sheet'!B62/'data sheet'!B$65 -> 0.20350112 | E36: ='data sheet'!C62/'data sheet'!C$65 -> 0.091530129 | F36: ='data sheet'!D62/'data sheet'!D$65 -> 0.079600612 | G36: ='data sheet'!E62/'data sheet'!E$65 -> 0.080083063 | H36: ='data sheet'!F62/'data sheet'!F$65 -> 0.078253658 | I36: ='data sheet'!G62/'data sheet'!G$65 -> 0.077928183 | J36: ='data sheet'!H62/'data sheet'!H$65 -> 0.078058989 | K36: ='data sheet'!I62/'data sheet'!I$65 -> 0.10936749 | ... M36: ='data sheet'!K62/'data sheet'!K$65 -> 0.15110203
B37: Investments | D37: ='data sheet'!B63/'data sheet'!B$65 -> 0.060569133 | E37: ='data sheet'!C63/'data sheet'!C$65 -> 0.072237228 | F37: ='data sheet'!D63/'data sheet'!D$65 -> 0.085757409 | G37: ='data sheet'!E63/'data sheet'!E$65 -> 0.024651309 | H37: ='data sheet'!F63/'data sheet'!F$65 -> 0.025226579 | I37: ='data sheet'!G63/'data sheet'!G$65 -> 0.043794701 | J37: ='data sheet'!H63/'data sheet'!H$65 -> 0.046525644 | K37: ='data sheet'!I63/'data sheet'!I$65 -> 0.029468936 | ... M37: ='data sheet'!K63/'data sheet'!K$65 -> 0.022486539
B38: Other Assets | D38: ='data sheet'!B73/'data sheet'!B$74 -> 0.11142071 | E38: ='data sheet'!C73/'data sheet'!C$74 -> 0.063137408 | F38: ='data sheet'!D73/'data sheet'!D$74 -> 0.14094796 | G38: ='data sheet'!E73/'data sheet'!E$74 -> 0.1595701 | H38: ='data sheet'!F73/'data sheet'!F$74 -> 0.16780352 | I38: ='data sheet'!G73/'data sheet'!G$74 -> 0.12236636 | J38: ='data sheet'!H73/'data sheet'!H$74 -> 0.13093432 | K38: ='data sheet'!I73/'data sheet'!I$74 -> 0.081014372 | ... M38: ='data sheet'!K73/'data sheet'!K$74 -> 0.05529354
B39: Receivables | D39: ='data sheet'!B66/'data sheet'!B$74 -> 0.068215444 | E39: ='data sheet'!C66/'data sheet'!C$74 -> 0.067190471 | F39: ='data sheet'!D66/'data sheet'!D$74 -> 0.059483484 | G39: ='data sheet'!E66/'data sheet'!E$74 -> 0.050740325 | H39: ='data sheet'!F66/'data sheet'!F$74 -> 0.031647352 | I39: ='data sheet'!G66/'data sheet'!G$74 -> 0.039112261 | J39: ='data sheet'!H66/'data sheet'!H$74 -> 0.043362218 | K39: ='data sheet'!I66/'data sheet'!I$74 -> 0.028932593 | ... M39: ='data sheet'!K66/'data sheet'!K$74 -> 0.019095648
B40: Inventory | D40: ='data sheet'!B67/'data sheet'!B$74 -> 0.11314382 | E40: ='data sheet'!C67/'data sheet'!C$74 -> 0.14383414 | F40: ='data sheet'!D67/'data sheet'!D$74 -> 0.13573567 | G40: ='data sheet'!E67/'data sheet'!E$74 -> 0.13599533 | H40: ='data sheet'!F67/'data sheet'!F$74 -> 0.1246993 | I40: ='data sheet'!G67/'data sheet'!G$74 -> 0.13642938 | J40: ='data sheet'!H67/'data sheet'!H$74 -> 0.17287763 | K40: ='data sheet'!I67/'data sheet'!I$74 -> 0.1906662 | ... M40: ='data sheet'!K67/'data sheet'!K$74 -> 0.1618753
B41: Cash & Bank | D41: ='data sheet'!B68/'data sheet'!B$74 -> 0.034973996 | E41: ='data sheet'!C68/'data sheet'!C$74 -> 0.028536533 | F41: ='data sheet'!D68/'data sheet'!D$74 -> 0.038030704 | G41: ='data sheet'!E68/'data sheet'!E$74 -> 0.014354602 | H41: ='data sheet'!F68/'data sheet'!F$74 -> 0.032328912 | I41: ='data sheet'!G68/'data sheet'!G$74 -> 0.023706282 | J41: ='data sheet'!H68/'data sheet'!H$74 -> 0.056295007 | K41: ='data sheet'!I68/'data sheet'!I$74 -> 0.046802584 | ... M41: ='data sheet'!K68/'data sheet'!K$74 -> 0.042282146

Sheet Ratio Analysis
B2: Ratio Analysis of - TATA STEEL LTD
B3: Years | C3: 42460 | D3: 42825 | E3: 43190 | F3: 43555 | G3: 43921 | H3: 44286 | I3: 44651 | J3: 45016 | K3: 45382 | L3: 45747 | M3: Trend | N3: Mean | O3: Median
B5: Sales Growth | C5: =IFERROR('HISTORICAL(FS)'!C8,0) -> - | D5: =IFERROR('HISTORICAL(FS)'!D8,0) -> 0.10135565 | E5: =IFERROR('HISTORICAL(FS)'!E8,0) -> 0.097504065 | F5: =IFERROR('HISTORICAL(FS)'!F8,0) -> 0.27927124 | G5: =IFERROR('HISTORICAL(FS)'!G8,0) -> -0.1132267 | H5: =IFERROR('HISTORICAL(FS)'!H8,0) -> 0.11916142 | I5: =IFERROR('HISTORICAL(FS)'!I8,0) -> 0.55906968 | J5: =IFERROR('HISTORICAL(FS)'!J8,0) -> -0.0024859898 | ... L5: =IFERROR('HISTORICAL(FS)'!L8,0) -> -0.046377073 | N5: =IFERROR(AVERAGE(D5:L5),0) -> 0.10399945 | O5: =IFERROR(MEDIAN(C5:L5),0) -> 0.097504065
B6: EBITDA Growth | C6: - | D6: =IFERROR('HISTORICAL(FS)'!D19/'HISTORICAL(FS)'!C19-1,0) -> -22.021736 | E6: =IFERROR('HISTORICAL(FS)'!E19/'HISTORICAL(FS)'!D19-1,0) -> 0.6306903 | F6: =IFERROR('HISTORICAL(FS)'!F19/'HISTORICAL(FS)'!E19-1,0) -> 0.36788877 | G6: =IFERROR('HISTORICAL(FS)'!G19/'HISTORICAL(FS)'!F19-1,0) -> -0.40436152 | H6: =IFERROR('HISTORICAL(FS)'!H19/'HISTORICAL(FS)'!G19-1,0) -> 0.74678779 | I6: =IFERROR('HISTORICAL(FS)'!I19/'HISTORICAL(FS)'!H19-1,0) -> 1.081347 | J6: =IFERROR('HISTORICAL(FS)'!J19/'HISTORICAL(FS)'!I19-1,0) -> -0.49125555 | K6: =IFERROR('HISTORICAL(FS)'!K19/'HISTORICAL(FS)'!J19-1,0) -> -0.31121332 | L6: =IFERROR('HISTORICAL(FS)'!L19/'HISTORICAL(FS)'!K19-1,0) -> 0.13711529 | N6: =IFERROR(AVERAGE(D6:L6),0) -> -2.2516374 | O6: =IFERROR(MEDIAN(C6:L6),0) -> 0.13711529
B7: EBIT Growth | C7: - | D7: =IFERROR('HISTORICAL(FS)'!D28/'HISTORICAL(FS)'!C28-1,0) -> -1.2362405 | E7: =IFERROR('HISTORICAL(FS)'!E28/'HISTORICAL(FS)'!D28-1,0) -> 3.267891 | F7: =IFERROR('HISTORICAL(FS)'!F28/'HISTORICAL(FS)'!E28-1,0) -> 0.39851906 | G7: =IFERROR('HISTORICAL(FS)'!G28/'HISTORICAL(FS)'!F28-1,0) -> -0.89600169 | H7: =IFERROR('HISTORICAL(FS)'!H28/'HISTORICAL(FS)'!G28-1,0) -> 8.1773694 | I7: =IFERROR('HISTORICAL(FS)'!I28/'HISTORICAL(FS)'!H28-1,0) -> 2.5807379 | J7: =IFERROR('HISTORICAL(FS)'!J28/'HISTORICAL(FS)'!I28-1,0) -> -0.65936393 | K7: =IFERROR('HISTORICAL(FS)'!K28/'HISTORICAL(FS)'!J28-1,0) -> -0.70850149 | L7: =IFERROR('HISTORICAL(FS)'!L28/'HISTORICAL(FS)'!K28-1,0) -> 0.55122998 | N7: =IFERROR(AVERAGE(D7:L7),0) -> 1.2750711 | O7: =IFERROR(MEDIAN(C7:L7),0) -> 0.39851906
B8: Net Profit Growth | C8: - | D8: =IFERROR('HISTORICAL(FS)'!D34/'HISTORICAL(FS)'!C34-1,0) -> -0.96500402 | E8: =IFERROR('HISTORICAL(FS)'!E34/'HISTORICAL(FS)'!D34-1,0) -> -19.037263 | F8: =IFERROR('HISTORICAL(FS)'!F34/'HISTORICAL(FS)'!E34-1,0) -> 0.11008091 | G8: =IFERROR('HISTORICAL(FS)'!G34/'HISTORICAL(FS)'!F34-1,0) -> -0.465997 | H8: =IFERROR('HISTORICAL(FS)'!H34/'HISTORICAL(FS)'!G34-1,0) -> 0.9742315 | I8: =IFERROR('HISTORICAL(FS)'!I34/'HISTORICAL(FS)'!H34-1,0) -> 4.0498476 | J8: =IFERROR('HISTORICAL(FS)'!J34/'HISTORICAL(FS)'!I34-1,0) -> -0.83914468 | K8: =IFERROR('HISTORICAL(FS)'!K34/'HISTORICAL(FS)'!J34-1,0) -> -0.83161121 | L8: =IFERROR('HISTORICAL(FS)'!L34/'HISTORICAL(FS)'!K34-1,0) -> 1.0966028 | N8: =IFERROR(AVERAGE(D8:L8),0) -> -1.7675842 | O8: =IFERROR(MEDIAN(C8:L8),0) -> -0.465997
B9: Divident Growth | C9: - | D9: =IFERROR('HISTORICAL(FS)'!D42/'HISTORICAL(FS)'!C42-1,0) -> 0.25000322 | E9: =IFERROR('HISTORICAL(FS)'!E42/'HISTORICAL(FS)'!D42-1,0) -> 0.18021551 | F9: =IFERROR('HISTORICAL(FS)'!F42/'HISTORICAL(FS)'!E42-1,0) -> 0.29997536 | G9: =IFERROR('HISTORICAL(FS)'!G42/'HISTORICAL(FS)'!F42-1,0) -> -0.23076148 | H9: =IFERROR('HISTORICAL(FS)'!H42/'HISTORICAL(FS)'!G42-1,0) -> 1.4617851 | I9: =IFERROR('HISTORICAL(FS)'!I42/'HISTORICAL(FS)'!H42-1,0) -> 1.0381154 | J9: =IFERROR('HISTORICAL(FS)'!J42/'HISTORICAL(FS)'!I42-1,0) -> -0.29459179 | K9: =IFERROR('HISTORICAL(FS)'!K42/'HISTORICAL(FS)'!J42-1,0) -> 1.5657977e-05 | L9: =IFERROR('HISTORICAL(FS)'!L42/'HISTORICAL(FS)'!K42-1,0) -> 0 | N9: =IFERROR(AVERAGE(D9:L9),0) -> 0.30052856 | O9: =IFERROR(MEDIAN(C9:L9),0) -> 0.18021551
B11: Gross Margin | C11: =IFERROR('HISTORICAL(FS)'!C14,0) -> 0.22289533 | D11: =IFERROR('HISTORICAL(FS)'!D14,0) -> 0.30919421 | E11: =IFERROR('HISTORICAL(FS)'!E14,0) -> 0.31269218 | F11: =IFERROR('HISTORICAL(FS)'!F14,0) -> 0.33030553 | G11: =IFERROR('HISTORICAL(FS)'!G14,0) -> 0.26646118 | H11: =IFERROR('HISTORICAL(FS)'!H14,0) -> 0.34188745 | I11: =IFERROR('HISTORICAL(FS)'!I14,0) -> 0.41135564 | J11: =IFERROR('HISTORICAL(FS)'!J14,0) -> 0.26719791 | ... L11: =IFERROR('HISTORICAL(FS)'!L14,0) -> 0.21427191 | N11: =IFERROR(AVERAGE(C11:L11),0) -> 0.28770546 | O11: =IFERROR('HISTORICAL(FS)'!O14,0) -> 0
B12: EBITDA Margin | C12: =IFERROR('HISTORICAL(FS)'!C20,0) -> -0.0061319248 | D12: =IFERROR('HISTORICAL(FS)'!D20,0) -> 0.11704094 | E12: =IFERROR('HISTORICAL(FS)'!E20,0) -> 0.17390143 | F12: =IFERROR('HISTORICAL(FS)'!F20,0) -> 0.18594792 | G12: =IFERROR('HISTORICAL(FS)'!G20,0) -> 0.12489972 | H12: =IFERROR('HISTORICAL(FS)'!H20,0) -> 0.19494355 | I12: =IFERROR('HISTORICAL(FS)'!I20,0) -> 0.26024826 | J12: =IFERROR('HISTORICAL(FS)'!J20,0) -> 0.13272983 | ... L12: =IFERROR('HISTORICAL(FS)'!L20,0) -> 0.11575986 | N12: =IFERROR(AVERAGE(C12:L12),0) -> 0.13964197 | O12: =IFERROR('HISTORICAL(FS)'!O20,0) -> 0
B13: EBIT Margin | C13: =IFERROR(('HISTORICAL(FS)'!C19-'HISTORICAL(FS)'!C25)/'HISTORICAL(FS)'!C7,0) -> -0.058172964 | D13: =IFERROR(('HISTORICAL(FS)'!D19-'HISTORICAL(FS)'!D25)/'HISTORICAL(FS)'!D7,0) -> 0.066525277 | E13: =IFERROR(('HISTORICAL(FS)'!E19-'HISTORICAL(FS)'!E25)/'HISTORICAL(FS)'!E7,0) -> 0.12731528 | F13: =IFERROR(('HISTORICAL(FS)'!F19-'HISTORICAL(FS)'!F25)/'HISTORICAL(FS)'!F7,0) -> 0.13938308 | G13: =IFERROR(('HISTORICAL(FS)'!G19-'HISTORICAL(FS)'!G25)/'HISTORICAL(FS)'!G7,0) -> 0.064529725 | H13: =IFERROR(('HISTORICAL(FS)'!H19-'HISTORICAL(FS)'!H25)/'HISTORICAL(FS)'!H7,0) -> 0.13593413 | I13: =IFERROR(('HISTORICAL(FS)'!I19-'HISTORICAL(FS)'!I25)/'HISTORICAL(FS)'!I7,0) -> 0.22294337 | J13: =IFERROR(('HISTORICAL(FS)'!J19-'HISTORICAL(FS)'!J25)/'HISTORICAL(FS)'!J7,0) -> 0.094369041 | ... L13: =IFERROR(('HISTORICAL(FS)'!L19-'HISTORICAL(FS)'!L25)/'HISTORICAL(FS)'!L7,0) -> 0.068074262 | N13: =IFERROR(AVERAGE(C13:L13),0) -> 0.091485992 | O13: =IFERROR(('HISTORICAL(FS)'!O19-'HISTORICAL(FS)'!O25)/'HISTORICAL(FS)'!O7,0) -> 0
B14: EBT Margin | C14: =IFERROR('HISTORICAL(FS)'!C29,0) -> -0.099573656 | D14: =IFERROR('HISTORICAL(FS)'!D29,0) -> 0.021358525 | E14: =IFERROR('HISTORICAL(FS)'!E29,0) -> 0.083057422 | F14: =IFERROR('HISTORICAL(FS)'!F29,0) -> 0.090799656 | G14: =IFERROR('HISTORICAL(FS)'!G29,0) -> 0.010648732 | H14: =IFERROR('HISTORICAL(FS)'!H29,0) -> 0.087321939 | I14: =IFERROR('HISTORICAL(FS)'!I29,0) -> 0.20055356 | J14: =IFERROR('HISTORICAL(FS)'!J29,0) -> 0.068486032 | ... L14: =IFERROR('HISTORICAL(FS)'!L29,0) -> 0.034483772 | N14: =IFERROR(AVERAGE(C14:L14),0) -> 0.051833497 | O14: =IFERROR('HISTORICAL(FS)'!O29,0) -> 0
B15: Net Profit Margin | C15: =IFERROR('HISTORICAL(FS)'!C35,0) -> -0.10634031 | D15: =IFERROR('HISTORICAL(FS)'!D35,0) -> -0.0033790023 | E15: =IFERROR('HISTORICAL(FS)'!E35,0) -> 0.055533239 | F15: =IFERROR('HISTORICAL(FS)'!F35,0) -> 0.048188677 | G15: =IFERROR('HISTORICAL(FS)'!G35,0) -> 0.029018575 | H15: =IFERROR('HISTORICAL(FS)'!H35,0) -> 0.051189565 | I15: =IFERROR('HISTORICAL(FS)'!I35,0) -> 0.16580369 | J15: =IFERROR('HISTORICAL(FS)'!J35,0) -> 0.026736873 | ... L15: =IFERROR('HISTORICAL(FS)'!L35,0) -> 0.010510907 | N15: =IFERROR(AVERAGE(C15:L15),0) -> 0.028204301 | O15: =IFERROR(MEDIAN(C15:L15),0) -> 0.027877724
B17: Sales Expenses % Sales | C17: =IFERROR('HISTORICAL(FS)'!C17,0) -> 0.22902726 | D17: =IFERROR('HISTORICAL(FS)'!D17,0) -> 0.19215326 | E17: =IFERROR('HISTORICAL(FS)'!E17,0) -> 0.13879074 | F17: =IFERROR('HISTORICAL(FS)'!F17,0) -> 0.14435762 | G17: =IFERROR('HISTORICAL(FS)'!G17,0) -> 0.14156147 | H17: =IFERROR('HISTORICAL(FS)'!H17,0) -> 0.1469439 | I17: =IFERROR('HISTORICAL(FS)'!I17,0) -> 0.15110738 | J17: =IFERROR('HISTORICAL(FS)'!J17,0) -> 0.13446808 | ... L17: =IFERROR('HISTORICAL(FS)'!L17,0) -> 0.098512047 | N17: =IFERROR(AVERAGE(C17:L17),0) -> 0.14806349 | O17: =IFERROR(MEDIAN(C17:L17),0) -> 0.14295954
B18: Depreciation % Sales | C18: =IFERROR('HISTORICAL(FS)'!C26,0) -> 0.052041039 | D18: =IFERROR('HISTORICAL(FS)'!D26,0) -> 0.050515666 | E18: =IFERROR('HISTORICAL(FS)'!E26,0) -> 0.046586153 | F18: =IFERROR('HISTORICAL(FS)'!F26,0) -> 0.046564832 | G18: =IFERROR('HISTORICAL(FS)'!G26,0) -> 0.060369992 | H18: =IFERROR('HISTORICAL(FS)'!H26,0) -> 0.059009416 | I18: =IFERROR('HISTORICAL(FS)'!I26,0) -> 0.03730489 | J18: =IFERROR('HISTORICAL(FS)'!J26,0) -> 0.038360784 | ... L18: =IFERROR('HISTORICAL(FS)'!L26,0) -> 0.047685597 | N18: =IFERROR(AVERAGE(C18:L18),0) -> 0.048155975 | O18: =IFERROR(MEDIAN(C18:L18),0) -> 0.047135875
B19: Operating income % Sales | C19: =IFERROR(C13,0) -> -0.058172964 | D19: =IFERROR(D13,0) -> 0.066525277 | E19: =IFERROR(E13,0) -> 0.12731528 | F19: =IFERROR(F13,0) -> 0.13938308 | G19: =IFERROR(G13,0) -> 0.064529725 | H19: =IFERROR(H13,0) -> 0.13593413 | I19: =IFERROR(I13,0) -> 0.22294337 | J19: =IFERROR(J13,0) -> 0.094369041 | ... L19: =IFERROR(L13,0) -> 0.068074262 | N19: =IFERROR(AVERAGE(C19:L19),0) -> 0.091485992 | O19: =IFERROR(MEDIAN(C19:L19),0) -> 0.081221651
B21: Return on Capital Employed | C21: =IFERROR(('HISTORICAL(FS)'!C19-'HISTORICAL(FS)'!C25)/(SUM('HISTORICAL(FS)'!C50:C52)),0) -> -0.047181153 | D21: =IFERROR(('HISTORICAL(FS)'!D19-'HISTORICAL(FS)'!D25)/(SUM('HISTORICAL(FS)'!D50:D52)),0) -> 0.061826653 | E21: =IFERROR(('HISTORICAL(FS)'!E19-'HISTORICAL(FS)'!E25)/(SUM('HISTORICAL(FS)'!E50:E52)),0) -> 0.10254692 | F21: =IFERROR(('HISTORICAL(FS)'!F19-'HISTORICAL(FS)'!F25)/(SUM('HISTORICAL(FS)'!F50:F52)),0) -> 0.12946991 | G21: =IFERROR(('HISTORICAL(FS)'!G19-'HISTORICAL(FS)'!G25)/(SUM('HISTORICAL(FS)'!G50:G52)),0) -> 0.047509827 | H21: =IFERROR(('HISTORICAL(FS)'!H19-'HISTORICAL(FS)'!H25)/(SUM('HISTORICAL(FS)'!H50:H52)),0) -> 0.13070294 | I21: =IFERROR(('HISTORICAL(FS)'!I19-'HISTORICAL(FS)'!I25)/(SUM('HISTORICAL(FS)'!I50:I52)),0) -> 0.2862517 | J21: =IFERROR(('HISTORICAL(FS)'!J19-'HISTORICAL(FS)'!J25)/(SUM('HISTORICAL(FS)'!J50:J52)),0) -> 0.12217019 | ... L21: =IFERROR(('HISTORICAL(FS)'!L19-'HISTORICAL(FS)'!L25)/(SUM('HISTORICAL(FS)'!L50:L52)),0) -> 0.079997126 | N21: =IFERROR(AVERAGE(C21:L21),0) -> 0.09823311 | O21: =IFERROR(MEDIAN(C21:L21),0) -> 0.091272021
B22: Retained Earnings % | C22: =IFERROR('HISTORICAL(FS)'!C45,0) -> 0 | D22: =IFERROR('HISTORICAL(FS)'!D45,0) -> 0 | E22: =IFERROR('HISTORICAL(FS)'!E45,0) -> 0.83271775 | F22: =IFERROR('HISTORICAL(FS)'!F45,0) -> 0.8041001 | G22: =IFERROR('HISTORICAL(FS)'!G45,0) -> 0.71780355 | H22: =IFERROR('HISTORICAL(FS)'!H45,0) -> 0.6262152 | I22: =IFERROR('HISTORICAL(FS)'!I45,0) -> 0.84602539 | J22: =IFERROR('HISTORICAL(FS)'!J45,0) -> 0.3242962 | ... L22: =IFERROR('HISTORICAL(FS)'!L45,0) -> 0 | N22: =IFERROR(AVERAGE(C22:L22),0) -> 0.41511582 | O22: =IFERROR(MEDIAN(C22:L22),0) -> 0.4752557
B23: Return on Equity % | C23: =IFERROR('HISTORICAL(FS)'!C34/SUM('HISTORICAL(FS)'!C50:C51),0) -> -0.24793798 | D23: =IFERROR('HISTORICAL(FS)'!D34/SUM('HISTORICAL(FS)'!D50:D51),0) -> -0.010033496 | E23: =IFERROR('HISTORICAL(FS)'!E34/SUM('HISTORICAL(FS)'!E50:E51),0) -> 0.11244209 | F23: =IFERROR('HISTORICAL(FS)'!F34/SUM('HISTORICAL(FS)'!F50:F51),0) -> 0.1102336 | G23: =IFERROR('HISTORICAL(FS)'!G34/SUM('HISTORICAL(FS)'!G50:G51),0) -> 0.055143844 | H23: =IFERROR('HISTORICAL(FS)'!H34/SUM('HISTORICAL(FS)'!H50:H51),0) -> 0.10789524 | I23: =IFERROR('HISTORICAL(FS)'!I34/SUM('HISTORICAL(FS)'!I50:I51),0) -> 0.35344508 | J23: =IFERROR('HISTORICAL(FS)'!J34/SUM('HISTORICAL(FS)'!J50:J51),0) -> 0.063119494 | ... L23: =IFERROR('HISTORICAL(FS)'!L34/SUM('HISTORICAL(FS)'!L50:L51),0) -> 0.025195671 | N23: =IFERROR(AVERAGE(C23:L23),0) -> 0.058140785 | O23: =IFERROR(MEDIAN(C23:L23),0) -> 0.059131669
B24: Self Sustained Growth Rate | C24: =IFERROR('Ratio Analysis'!C22*'Ratio Analysis'!C23,0) -> 0 | D24: =IFERROR('Ratio Analysis'!D22*'Ratio Analysis'!D23,0) -> 0 | E24: =IFERROR('Ratio Analysis'!E22*'Ratio Analysis'!E23,0) -> 0.093632527 | F24: =IFERROR('Ratio Analysis'!F22*'Ratio Analysis'!F23,0) -> 0.088638853 | G24: =IFERROR('Ratio Analysis'!G22*'Ratio Analysis'!G23,0) -> 0.039582447 | H24: =IFERROR('Ratio Analysis'!H22*'Ratio Analysis'!H23,0) -> 0.06756564 | I24: =IFERROR('Ratio Analysis'!I22*'Ratio Analysis'!I23,0) -> 0.29902351 | J24: =IFERROR('Ratio Analysis'!J22*'Ratio Analysis'!J23,0) -> 0.020469412 | ... L24: =IFERROR('Ratio Analysis'!L22*'Ratio Analysis'!L23,0) -> 0 | N24: =IFERROR(AVERAGE(C24:L24),0) -> 0.060891239 | O24: =IFERROR(MEDIAN(C24:L24),0) -> 0.03002593
B25: Interest Coverage Ratio | C25: =IFERROR(('HISTORICAL(FS)'!C19-'HISTORICAL(FS)'!C25)/'HISTORICAL(FS)'!C22,0) -> -1.4051206 | D25: =IFERROR(('HISTORICAL(FS)'!D19-'HISTORICAL(FS)'!D25)/'HISTORICAL(FS)'!D22,0) -> 1.4728816 | E25: =IFERROR(('HISTORICAL(FS)'!E19-'HISTORICAL(FS)'!E25)/'HISTORICAL(FS)'!E22,0) -> 2.8766706 | F25: =IFERROR(('HISTORICAL(FS)'!F19-'HISTORICAL(FS)'!F25)/'HISTORICAL(FS)'!F22,0) -> 2.868943 | G25: =IFERROR(('HISTORICAL(FS)'!G19-'HISTORICAL(FS)'!G25)/'HISTORICAL(FS)'!G22,0) -> 1.1976343 | H25: =IFERROR(('HISTORICAL(FS)'!H19-'HISTORICAL(FS)'!H25)/'HISTORICAL(FS)'!H22,0) -> 2.796297 | I25: =IFERROR(('HISTORICAL(FS)'!I19-'HISTORICAL(FS)'!I25)/'HISTORICAL(FS)'!I22,0) -> 9.9573578 | J25: =IFERROR(('HISTORICAL(FS)'!J19-'HISTORICAL(FS)'!J25)/'HISTORICAL(FS)'!J22,0) -> 3.6459841 | ... L25: =IFERROR(('HISTORICAL(FS)'!L19-'HISTORICAL(FS)'!L25)/'HISTORICAL(FS)'!L22,0) -> 2.0265933 | N25: =IFERROR(AVERAGE(C25:L25),0) -> 2.7084347 | O25: =IFERROR(MEDIAN(C25:L25),0) -> 2.4114451
B27: Debtor Turnover Ratio | C27: =IFERROR('HISTORICAL(FS)'!C7/'HISTORICAL(FS)'!C62,0) -> 8.4504277 | D27: =IFERROR('HISTORICAL(FS)'!D7/'HISTORICAL(FS)'!D62,0) -> 9.6919966 | E27: =IFERROR('HISTORICAL(FS)'!E7/'HISTORICAL(FS)'!E62,0) -> 9.9270163 | F27: =IFERROR('HISTORICAL(FS)'!F7/'HISTORICAL(FS)'!F62,0) -> 13.349335 | G27: =IFERROR('HISTORICAL(FS)'!G7/'HISTORICAL(FS)'!G62,0) -> 17.732181 | H27: =IFERROR('HISTORICAL(FS)'!H7/'HISTORICAL(FS)'!H62,0) -> 16.402518 | I27: =IFERROR('HISTORICAL(FS)'!I7/'HISTORICAL(FS)'!I62,0) -> 19.92084 | J27: =IFERROR('HISTORICAL(FS)'!J7/'HISTORICAL(FS)'!J62,0) -> 29.471432 | ... L27: =IFERROR('HISTORICAL(FS)'!L7/'HISTORICAL(FS)'!L62,0) -> 41.547532 | N27: =IFERROR(AVERAGE(C27:L27),0) -> 20.30814 | O27: =IFERROR(MEDIAN(C27:L27),0) -> 17.06735
B28: Creditor Turnover Ratio | C28: =IFERROR('HISTORICAL(FS)'!C7/'HISTORICAL(FS)'!C53,0) -> 1.9928798 | D28: =IFERROR('HISTORICAL(FS)'!D7/'HISTORICAL(FS)'!D53,0) -> 2.1757736 | E28: =IFERROR('HISTORICAL(FS)'!E7/'HISTORICAL(FS)'!E53,0) -> 2.2125526 | F28: =IFERROR('HISTORICAL(FS)'!F7/'HISTORICAL(FS)'!F53,0) -> 2.5014063 | G28: =IFERROR('HISTORICAL(FS)'!G7/'HISTORICAL(FS)'!G53,0) -> 2.359989 | H28: =IFERROR('HISTORICAL(FS)'!H7/'HISTORICAL(FS)'!H53,0) -> 1.9277973 | I28: =IFERROR('HISTORICAL(FS)'!I7/'HISTORICAL(FS)'!I53,0) -> 2.6397571 | J28: =IFERROR('HISTORICAL(FS)'!J7/'HISTORICAL(FS)'!J53,0) -> 2.4979585 | ... L28: =IFERROR('HISTORICAL(FS)'!L7/'HISTORICAL(FS)'!L53,0) -> 2.4421459 | N28: =IFERROR(AVERAGE(C28:L28),0) -> 2.329111 | O28: =IFERROR(MEDIAN(C28:L28),0) -> 2.4010674
B29: Inventory Turnover | C29: =IFERROR('HISTORICAL(FS)'!C7/'HISTORICAL(FS)'!C63,0) -> 5.0948403 | D29: =IFERROR('HISTORICAL(FS)'!D7/'HISTORICAL(FS)'!D63,0) -> 4.527505 | E29: =IFERROR('HISTORICAL(FS)'!E7/'HISTORICAL(FS)'!E63,0) -> 4.3503193 | F29: =IFERROR('HISTORICAL(FS)'!F7/'HISTORICAL(FS)'!F63,0) -> 4.9806827 | G29: =IFERROR('HISTORICAL(FS)'!G7/'HISTORICAL(FS)'!G63,0) -> 4.5002385 | H29: =IFERROR('HISTORICAL(FS)'!H7/'HISTORICAL(FS)'!H63,0) -> 4.7023564 | I29: =IFERROR('HISTORICAL(FS)'!I7/'HISTORICAL(FS)'!I63,0) -> 4.996666 | J29: =IFERROR('HISTORICAL(FS)'!J7/'HISTORICAL(FS)'!J63,0) -> 4.4721348 | ... L29: =IFERROR('HISTORICAL(FS)'!L7/'HISTORICAL(FS)'!L63,0) -> 4.9011618 | N29: =IFERROR(AVERAGE(C29:L29),0) -> 4.7187874 | O29: =IFERROR(MEDIAN(C29:L29),0) -> 4.6821626
B30: Fixed Asset Turnover | C30: =IFERROR('HISTORICAL(FS)'!C7/'HISTORICAL(FS)'!C56,0) -> 1.4122584 | D30: =IFERROR('HISTORICAL(FS)'!D7/'HISTORICAL(FS)'!D56,0) -> 1.220559 | E30: =IFERROR('HISTORICAL(FS)'!E7/'HISTORICAL(FS)'!E56,0) -> 1.2824433 | F30: =IFERROR('HISTORICAL(FS)'!F7/'HISTORICAL(FS)'!F56,0) -> 1.2670088 | G30: =IFERROR('HISTORICAL(FS)'!G7/'HISTORICAL(FS)'!G56,0) -> 1.0391376 | H30: =IFERROR('HISTORICAL(FS)'!H7/'HISTORICAL(FS)'!H56,0) -> 1.1524743 | I30: =IFERROR('HISTORICAL(FS)'!I7/'HISTORICAL(FS)'!I56,0) -> 1.8303184 | J30: =IFERROR('HISTORICAL(FS)'!J7/'HISTORICAL(FS)'!J56,0) -> 1.6597345 | ... L30: =IFERROR('HISTORICAL(FS)'!L7/'HISTORICAL(FS)'!L56,0) -> 1.4481256 | N30: =IFERROR(AVERAGE(C30:L30),0) -> 1.3852037 | O30: =IFERROR(MEDIAN(C30:L30),0) -> 1.3473509
B31: Capital Turnover Ratio | C31: =IFERROR('HISTORICAL(FS)'!C7/SUM('HISTORICAL(FS)'!C50:C51),0) -> 2.3315521 | D31: =IFERROR('HISTORICAL(FS)'!D7/SUM('HISTORICAL(FS)'!D50:D51),0) -> 2.9693665 | E31: =IFERROR('HISTORICAL(FS)'!E7/SUM('HISTORICAL(FS)'!E50:E51),0) -> 2.0247711 | F31: =IFERROR('HISTORICAL(FS)'!F7/SUM('HISTORICAL(FS)'!F50:F51),0) -> 2.2875416 | G31: =IFERROR('HISTORICAL(FS)'!G7/SUM('HISTORICAL(FS)'!G50:G51),0) -> 1.9002947 | H31: =IFERROR('HISTORICAL(FS)'!H7/SUM('HISTORICAL(FS)'!H50:H51),0) -> 2.1077585 | I31: =IFERROR('HISTORICAL(FS)'!I7/SUM('HISTORICAL(FS)'!I50:I51),0) -> 2.1317082 | J31: =IFERROR('HISTORICAL(FS)'!J7/SUM('HISTORICAL(FS)'!J50:J51),0) -> 2.3607657 | ... L31: =IFERROR('HISTORICAL(FS)'!L7/SUM('HISTORICAL(FS)'!L50:L51),0) -> 2.3970977 | N31: =IFERROR(AVERAGE(C31:L31),0) -> 2.3000875 | O31: =IFERROR(MEDIAN(C31:L31),0) -> 2.3095469
B33: Debtor Days | C33: =IFERROR(365/C27,0) -> 43.19308 | D33: =IFERROR(365/D27,0) -> 37.659939 | E33: =IFERROR(365/E27,0) -> 36.768349 | F33: =IFERROR(365/F27,0) -> 27.342187 | G33: =IFERROR(365/G27,0) -> 20.584045 | H33: =IFERROR(365/H27,0) -> 22.252681 | I33: =IFERROR(365/I27,0) -> 18.322521 | J33: =IFERROR(365/J27,0) -> 12.384875 | ... L33: =IFERROR(365/L27,0) -> 8.7851187 | N33: =IFERROR(365/N27,0) -> 17.973089 | O33: =IFERROR(365/O27,0) -> 21.385863
B34: Payable Days | C34: =IFERROR(365/C28,0) -> 183.15204 | D34: =IFERROR(365/D28,0) -> 167.75643 | E34: =IFERROR(365/E28,0) -> 164.96783 | F34: =IFERROR(365/F28,0) -> 145.91792 | G34: =IFERROR(365/G28,0) -> 154.66174 | H34: =IFERROR(365/H28,0) -> 189.33526 | I34: =IFERROR(365/I28,0) -> 138.2703 | J34: =IFERROR(365/J28,0) -> 146.11932 | ... L34: =IFERROR(365/L28,0) -> 149.45872 | N34: =IFERROR(365/N28,0) -> 156.71215 | O34: =IFERROR(365/O28,0) -> 152.01572
B35: Inventory Days | C35: =IFERROR(365/C29,0) -> 71.641107 | D35: =IFERROR(365/D29,0) -> 80.618353 | E35: =IFERROR(365/E29,0) -> 83.901887 | F35: =IFERROR(365/F29,0) -> 73.283126 | G35: =IFERROR(365/G29,0) -> 81.106812 | H35: =IFERROR(365/H29,0) -> 77.620658 | I35: =IFERROR(365/I29,0) -> 73.048709 | J35: =IFERROR(365/J29,0) -> 81.616503 | ... L35: =IFERROR(365/L29,0) -> 74.472139 | N35: =IFERROR(365/N29,0) -> 77.350381 | O35: =IFERROR(365/O29,0) -> 77.95543
B36: Cash Conversion Cycle | C36: =IFERROR(SUM(C33+C35)-C34,0) -> -68.31785 | D36: =IFERROR(SUM(D33+D35)-D34,0) -> -49.478134 | E36: =IFERROR(SUM(E33+E35)-E34,0) -> -44.297593 | F36: =IFERROR(SUM(F33+F35)-F34,0) -> -45.292607 | G36: =IFERROR(SUM(G33+G35)-G34,0) -> -52.970883 | H36: =IFERROR(SUM(H33+H35)-H34,0) -> -89.461918 | I36: =IFERROR(SUM(I33+I35)-I34,0) -> -46.899069 | J36: =IFERROR(SUM(J33+J35)-J34,0) -> -52.117944 | ... L36: =IFERROR(SUM(L33+L35)-L34,0) -> -66.201461 | N36: =IFERROR(365/N30,0) -> 263.49915 | O36: =IFERROR(365/O30,0) -> 270.90197
B38: CFO/Sales | C38: =IFERROR('HISTORICAL(FS)'!#REF!/'HISTORICAL(FS)'!C7,0) -> 0 | D38: =IFERROR('HISTORICAL(FS)'!#REF!/'HISTORICAL(FS)'!D7,0) -> 0 | E38: =IFERROR('HISTORICAL(FS)'!#REF!/'HISTORICAL(FS)'!E7,0) -> 0 | F38: =IFERROR('HISTORICAL(FS)'!#REF!/'HISTORICAL(FS)'!F7,0) -> 0 | G38: =IFERROR('HISTORICAL(FS)'!#REF!/'HISTORICAL(FS)'!G7,0) -> 0 | H38: =IFERROR('HISTORICAL(FS)'!#REF!/'HISTORICAL(FS)'!H7,0) -> 0 | I38: =IFERROR('HISTORICAL(FS)'!#REF!/'HISTORICAL(FS)'!I7,0) -> 0 | J38: =IFERROR('HISTORICAL(FS)'!#REF!/'HISTORICAL(FS)'!J7,0) -> 0 | ... L38: =IFERROR('HISTORICAL(FS)'!#REF!/'HISTORICAL(FS)'!L7,0) -> 0 | N38: =IFERROR(AVERAGE(C38:L38),0) -> 0 | O38: =IFERROR(MEDIAN(C38:L38),0) -> 0
B39: CFO/Total Assets | C39: =IFERROR('HISTORICAL(FS)'!#REF!/'HISTORICAL(FS)'!C67,0) -> 0 | D39: =IFERROR('HISTORICAL(FS)'!#REF!/'HISTORICAL(FS)'!D67,0) -> 0 | E39: =IFERROR('HISTORICAL(FS)'!#REF!/'HISTORICAL(FS)'!E67,0) -> 0 | F39: =IFERROR('HISTORICAL(FS)'!#REF!/'HISTORICAL(FS)'!F67,0) -> 0 | G39: =IFERROR('HISTORICAL(FS)'!#REF!/'HISTORICAL(FS)'!G67,0) -> 0 | H39: =IFERROR('HISTORICAL(FS)'!#REF!/'HISTORICAL(FS)'!H67,0) -> 0 | I39: =IFERROR('HISTORICAL(FS)'!#REF!/'HISTORICAL(FS)'!I67,0) -> 0 | J39: =IFERROR('HISTORICAL(FS)'!#REF!/'HISTORICAL(FS)'!J67,0) -> 0 | ... L39: =IFERROR('HISTORICAL(FS)'!#REF!/'HISTORICAL(FS)'!L67,0) -> 0 | N39: =IFERROR(AVERAGE(C39:L39),0) -> 0 | O39: =IFERROR(MEDIAN(C39:L39),0) -> 0
B40: CFO/Total Debt | C40: =IFERROR('HISTORICAL(FS)'!#REF!/'HISTORICAL(FS)'!C52,0) -> 0 | D40: =IFERROR('HISTORICAL(FS)'!#REF!/'HISTORICAL(FS)'!D52,0) -> 0 | E40: =IFERROR('HISTORICAL(FS)'!#REF!/'HISTORICAL(FS)'!E52,0) -> 0 | F40: =IFERROR('HISTORICAL(FS)'!#REF!/'HISTORICAL(FS)'!F52,0) -> 0 | G40: =IFERROR('HISTORICAL(FS)'!#REF!/'HISTORICAL(FS)'!G52,0) -> 0 | H40: =IFERROR('HISTORICAL(FS)'!#REF!/'HISTORICAL(FS)'!H52,0) -> 0 | I40: =IFERROR('HISTORICAL(FS)'!#REF!/'HISTORICAL(FS)'!I52,0) -> 0 | J40: =IFERROR('HISTORICAL(FS)'!#REF!/'HISTORICAL(FS)'!J52,0) -> 0 | ... L40: =IFERROR('HISTORICAL(FS)'!#REF!/'HISTORICAL(FS)'!L52,0) -> 0 | N40: =IFERROR(AVERAGE(C40:L40),0) -> 0 | O40: =IFERROR(MEDIAN(C40:L40),0) -> 0

Sheet Forecasting 
B3: TATA STEEL LTD - FORECASTING
B6: TATA STEEL LTD - Sales Forecasting | G6: TATA STEEL LTD - EBITDA Forecasting | L6: TATA STEEL LTD - EBIT Forecasting | Q6: TATA STEEL LTD - Net Profit Forecasting
B7: Year Weight | C7: Year | D7: Sales | E7: Sales Growth | G7: Year Weight | H7: Year | I7: EBITDA | J7: EBITDA Growth | L7: Year Weight | M7: Year | N7: EBIT | O7: EBIT Growth | Q7: Year Weight | R7: Year | S7: Net Profit | T7: Net Profit Growth
B8: 1 | C8: 2016 | D8: 101965 | G8: 1 | H8: 2016 | I8: -625.24 | L8: 1 | M8: 2016 | N8: -10153 | Q8: 1 | R8: 2016 | S8: -10842.96
B9: =1+B8 -> 2 | C9: =1+C8 -> 2017 | D9: 112299 | E9: =IFERROR(D9/D8-1,0) -> 0.1013485 | G9: =1+G8 -> 2 | H9: =1+H8 -> 2017 | I9: 13143.63 | J9: =IFERROR(I9/I8-1,0) -> -22.021736 | L9: 2 | M9: 2017 | N9: 2398.55 | O9: =IFERROR(N9/N8-1,0) -> -1.2362405 | Q9: =1+Q8 -> 2 | R9: =1+R8 -> 2017 | S9: -379.46 | T9: =IFERROR(S9/S8-1,0) -> -0.96500402
B10: =1+B9 -> 3 | C10: =1+C9 -> 2018 | D10: 123249 | E10: =IFERROR(D10/D9-1,0) -> 0.097507547 | G10: =1+G9 -> 3 | H10: =1+H9 -> 2018 | I10: 21433.19 | J10: =IFERROR(I10/I9-1,0) -> 0.6306903 | L10: 3 | M10: 2018 | N10: 10236.75 | O10: =IFERROR(N10/N9-1,0) -> 3.267891 | Q10: =1+Q9 -> 3 | R10: =1+R9 -> 2018 | S10: 6844.42 | T10: =IFERROR(S10/S9-1,0) -> -19.037263
B11: =1+B10 -> 4 | C11: =1+C10 -> 2019 | D11: 157669 | E11: =IFERROR(D11/D10-1,0) -> 0.27927204 | G11: =1+G10 -> 4 | H11: =1+H10 -> 2019 | I11: 29318.22 | J11: =IFERROR(I11/I10-1,0) -> 0.36788877 | L11: 4 | M11: 2019 | N11: 14316.29 | O11: =IFERROR(N11/N10-1,0) -> 0.39851906 | Q11: =1+Q10 -> 4 | R11: =1+R10 -> 2019 | S11: 7597.86 | T11: =IFERROR(S11/S10-1,0) -> 0.11008091
B12: =1+B11 -> 5 | C12: =1+C11 -> 2020 | D12: 139817 | E12: =IFERROR(D12/D11-1,0) -> -0.11322454 | G12: =1+G11 -> 5 | H12: =1+H11 -> 2020 | I12: 17463.06 | J12: =IFERROR(I12/I11-1,0) -> -0.40436152 | L12: 5 | M12: 2020 | N12: 1488.87 | O12: =IFERROR(N12/N11-1,0) -> -0.89600169 | Q12: =1+Q11 -> 5 | R12: =1+R11 -> 2020 | S12: 4057.28 | T12: =IFERROR(S12/S11-1,0) -> -0.465997
B13: =1+B12 -> 6 | C13: =1+C12 -> 2021 | D13: 156477 | E13: =IFERROR(D13/D12-1,0) -> 0.11915575 | G13: =1+G12 -> 6 | H13: =1+H12 -> 2021 | I13: 30504.26 | J13: =IFERROR(I13/I12-1,0) -> 0.74678779 | L13: 6 | M13: 2021 | N13: 13663.91 | O13: =IFERROR(N13/N12-1,0) -> 8.1773694 | Q13: =1+Q12 -> 6 | R13: =1+R12 -> 2021 | S13: 8010.01 | T13: =IFERROR(S13/S12-1,0) -> 0.9742315
B14: =1+B13 -> 7 | C14: =1+C13 -> 2022 | D14: 243959 | E14: =IFERROR(D14/D13-1,0) -> 0.55907258 | G14: =1+G13 -> 7 | H14: =1+H13 -> 2022 | I14: 63489.95 | J14: =IFERROR(I14/I13-1,0) -> 1.081347 | L14: 7 | M14: 2022 | N14: 48926.88 | O14: =IFERROR(N14/N13-1,0) -> 2.5807379 | Q14: =1+Q13 -> 7 | R14: =1+R13 -> 2022 | S14: 40449.33 | T14: =IFERROR(S14/S13-1,0) -> 4.0498476
B15: =1+B14 -> 8 | C15: =1+C14 -> 2023 | D15: 243353 | E15: =IFERROR(D15/D14-1,0) -> -0.002484024 | G15: =1+G14 -> 8 | H15: =1+H14 -> 2023 | I15: 32300.16 | J15: =IFERROR(I15/I14-1,0) -> -0.49125555 | L15: 8 | M15: 2023 | N15: 16666.26 | O15: =IFERROR(N15/N14-1,0) -> -0.65936393 | Q15: =1+Q14 -> 8 | R15: =1+R14 -> 2023 | S15: 6506.49 | T15: =IFERROR(S15/S14-1,0) -> -0.83914468
B16: =1+B15 -> 9 | C16: =1+C15 -> 2024 | D16: 229171 | E16: =IFERROR(D16/D15-1,0) -> -0.058277482 | G16: =1+G15 -> 9 | H16: =1+H15 -> 2024 | I16: 22247.92 | J16: =IFERROR(I16/I15-1,0) -> -0.31121332 | L16: 9 | M16: 2024 | N16: 4858.19 | O16: =IFERROR(N16/N15-1,0) -> -0.70850149 | Q16: =1+Q15 -> 9 | R16: =1+R15 -> 2024 | S16: 1095.62 | T16: =IFERROR(S16/S15-1,0) -> -0.83161121
B17: =1+B16 -> 10 | C17: =1+C16 -> 2025 | D17: 218543 | E17: =IFERROR(D17/D16-1,0) -> -0.04637585 | G17: =1+G16 -> 10 | H17: =1+H16 -> 2025 | I17: 25298.45 | J17: =IFERROR(I17/I16-1,0) -> 0.13711529 | L17: 10 | M17: 2025 | N17: 7536.17 | O17: =IFERROR(N17/N16-1,0) -> 0.55122998 | Q17: =1+Q16 -> 10 | R17: =1+R16 -> 2025 | S17: 2297.08 | T17: =IFERROR(S17/S16-1,0) -> 1.0966028
B18: =1+B17 -> 11 | C18: =1+C17 -> 2026 | D18: =FORECAST(B18,D8:D17,B8:B17) -> 264095.4 | E18: =IFERROR(D18/D17-1,0) -> 0.20843678 | G18: =1+G17 -> 11 | H18: =1+H17 -> 2026 | I18: =FORECAST(G18,I8:I17,G8:G17) -> 41021.843 | J18: =IFERROR(I18/I17-1,0) -> 0.62151605 | L18: 11 | M18: 2026 | N18: =FORECAST(L18,N8:N17,L8:L17) -> 21813.033 | O18: =IFERROR(N18/N17-1,0) -> 1.8944454 | Q18: =1+Q17 -> 11 | R18: =1+R17 -> 2026 | S18: =FORECAST(Q18,S8:S17,Q8:Q17) -> 14210.347 | T18: =IFERROR(S18/S17-1,0) -> 5.1862658
B19: =1+B18 -> 12 | C19: =1+C18 -> 2027 | D19: =FORECAST(B19,D9:D18,B9:B18) -> 281824.09 | E19: =IFERROR(D19/D18-1,0) -> 0.067129883 | G19: =1+G18 -> 12 | H19: =1+H18 -> 2027 | I19: =FORECAST(G19,I9:I18,G9:G18) -> 40292.276 | J19: =IFERROR(I19/I18-1,0) -> -0.017784841 | L19: 12 | M19: 2027 | N19: =FORECAST(L19,N9:N18,L9:L18) -> 20501.521 | O19: =IFERROR(N19/N18-1,0) -> -0.060125138 | Q19: =1+Q18 -> 12 | R19: =1+R18 -> 2027 | S19: =FORECAST(Q19,S9:S18,Q9:Q18) -> 12627.319 | T19: =IFERROR(S19/S18-1,0) -> -0.1113997
B20: =1+B19 -> 13 | C20: =1+C19 -> 2028 | D20: =FORECAST(B20,D10:D19,B10:B19) -> 298591.3 | E20: =IFERROR(D20/D19-1,0) -> 0.059495306 | G20: =1+G19 -> 13 | H20: =1+H19 -> 2028 | I20: =FORECAST(G20,I10:I19,G10:G19) -> 40166.109 | J20: =IFERROR(I20/I19-1,0) -> -0.0031313004 | L20: 13 | M20: 2028 | N20: =FORECAST(L20,N10:N19,L10:L19) -> 19881.416 | O20: =IFERROR(N20/N19-1,0) -> -0.030246784 | Q20: =1+Q19 -> 13 | R20: =1+R19 -> 2028 | S20: =FORECAST(Q20,S10:S19,Q10:Q19) -> 11531.125 | T20: =IFERROR(S20/S19-1,0) -> -0.086811269
B21: =1+B20 -> 14 | C21: =1+C20 -> 2029 | D21: =FORECAST(B21,D11:D20,B11:B20) -> 313683.73 | E21: =IFERROR(D21/D20-1,0) -> 0.050545417 | G21: =1+G20 -> 14 | H21: =1+H20 -> 2029 | I21: =FORECAST(G21,I11:I20,G11:G20) -> 40390.114 | J21: =IFERROR(I21/I20-1,0) -> 0.0055769782 | L21: 14 | M21: 2029 | N21: =FORECAST(L21,N11:N20,L11:L20) -> 19896.591 | O21: =IFERROR(N21/N20-1,0) -> 0.00076326609 | Q21: =1+Q20 -> 14 | R21: =1+R20 -> 2029 | S21: =FORECAST(Q21,S11:S20,Q11:Q20) -> 11055.704 | T21: =IFERROR(S21/S20-1,0) -> -0.04122942
B22: =1+B21 -> 15 | C22: =1+C21 -> 2030 | D22: =FORECAST(B22,D12:D21,B12:B21) -> 332302.3 | E22: =IFERROR(D22/D21-1,0) -> 0.059354595 | G22: =1+G21 -> 15 | H22: =1+H21 -> 2030 | I22: =FORECAST(G22,I12:I21,G12:G21) -> 41557.535 | J22: =IFERROR(I22/I21-1,0) -> 0.028903636 | L22: 15 | M22: 2030 | N22: =FORECAST(L22,N12:N21,L12:L21) -> 20362.735 | O22: =IFERROR(N22/N21-1,0) -> 0.023428352 | Q22: =1+Q21 -> 15 | R22: =1+R21 -> 2030 | S22: =FORECAST(Q22,S12:S21,Q12:Q21) -> 10278.584 | T22: =IFERROR(S22/S21-1,0) -> -0.070291314

Sheet DCF Modelling(WACC)
B3: WACC Calculation of TATA STEEL LTD
B6: Weighted Average Cost of Capital
B8: All figures are in INR unless stated otherwise.
B10: Peer comps
I11: Debt / | J11: Debt / | K11: Levered | L11: Unlevered
B12: Name of the comp | D12: Country | E12: Total Debt | G12: Total Equity | H12: Tax Rate1 | I12: Equity | J12: Capital | K12: Beta 2 | L12: Beta 3
B14: JSW Steel | D14: India | E14: 101107 | G14: 285152.14 | H14: 0.3 | I14: =E14/G14 -> 0.35457212 | J14: =E14/(E14+G14) -> 0.2617595 | K14: 1.18 | L14: =K14/(1+(1-H14)*I14) -> 0.94536095
